Workbook

Sheet Szabásjegyzék
A1: Címke-ID (MPR alap) | B1: Megnevezés | C1: Modul | D1: Gyártási típus | E1: Anyag | F1: Anyag megnevezés | G1: Vastagság mm | H1: Kész hossz L | I1: Kész szél. W | J1: Élzárás előtt L | K1: Élzárás előtt W | L1: Nyers L | M1: Nyers W | N1: Db | O1: Szálirány | P1: A oldal | Q1: E1 | R1: E2 | S1: E3 | T1: E4 | U1: Élanyag (élzárt élek) | V1: Ütköző élek | W1: Furat A | X1: Furat B | Y1: Furat él | Z1: MPR fájlok | AA1: Felület m² | AB1: Élzáró fm | AC1: Nyitott / megjegyzés | AD1: Élkód (asztalos-sorrend) | AE1: DWG réteg-azonosító
A2: S16_D1-L | B2: D1 korpuszoldal | C2: D1 | D2: LAP | E2: M01 | F2: 18 mm kétoldalt melaminos grafitszürke bútorlap | G2: 18 | H2: 337 | I2: 402 | J2: 336.2 | K2: 402 | L2: 337.2 | M2: 402 | N2: 1 | O2: – | P2: -X (bal) | Q2: 0 | R2: V | S2: 0 | T2: 0 | U2: ABS 0,8 mm Egger U741 ST9 (dekoregyező) | V2: E1+E4 | W2: 0 | X2: 8 | Y2: 8 | Z2: S16_D1-L_A.mpr, S16_D1-L_B.mpr | AA2: =H2*I2/1000000*N2 -> 0.135474 | AB2: =(IF(Q2="V",H2,0)+IF(S2="V",H2,0)+IF(R2="V",I2,0)+IF(T2="V",I2,0))/1000*N2 -> 0.402 | AD2: V000 (E2-E4-E1-E3) | AE2: #16001
A3: S16_D1-R | B3: D1 korpuszoldal | C3: D1 | D3: LAP | E3: M01 | F3: 18 mm kétoldalt melaminos grafitszürke bútorlap | G3: 18 | H3: 337 | I3: 402 | J3: 336.2 | K3: 402 | L3: 337.2 | M3: 402 | N3: 1 | O3: – | P3: -X (bal) | Q3: 0 | R3: V | S3: 0 | T3: 0 | U3: ABS 0,8 mm Egger U741 ST9 (dekoregyező) | V3: E1+E4 | W3: 8 | X3: 0 | Y3: 8 | Z3: S16_D1-R_A.mpr | AA3: =H3*I3/1000000*N3 -> 0.135474 | AB3: =(IF(Q3="V",H3,0)+IF(S3="V",H3,0)+IF(R3="V",I3,0)+IF(T3="V",I3,0))/1000*N3 -> 0.402 | AD3: V000 (E2-E4-E1-E3) | AE3: #16002
A4: S16_D1-T | B4: D1 fenék/tető | C4: D1 | D4: LAP | E4: M02 | F4: Szatén sötét barnásgrafit keret | G4: 18 | H4: 399 | I4: 337 | J4: 399 | K4: 337 | L4: 409 | M4: 347 | N4: 1 | O4: – | P4: +Z (fent) | Q4: F | R4: 0 | S4: F | T4: 0 | U4: festett él (festett MDF) | V4: E1+E4 | W4: 0 | X4: 0 | Y4: 6 | Z4: S16_D1-T_A.mpr | AA4: =H4*I4/1000000*N4 -> 0.134463 | AB4: =(IF(Q4="V",H4,0)+IF(S4="V",H4,0)+IF(R4="V",I4,0)+IF(T4="V",I4,0))/1000*N4 -> 0 | AD4: FF00 (E1-E3-E2-E4) | AE4: #16003
A5: S16_D1-BACK | B5: D1 bontható hát | C5: D1 | D5: LAP | E5: M08 | F5: 8 mm grafit hátlap | G5: 8 | H5: 399 | I5: 384 | J5: 399 | K5: 384 | L5: 399 | M5: 384 | N5: 1 | O5: – | P5: +Y (elöl (szoba)) | Q5: 0 | R5: 0 | S5: 0 | T5: 0 | U5: – | V5: E1+E4 | W5: 0 | X5: 0 | Y5: 0 | Z5: – | AA5: =H5*I5/1000000*N5 -> 0.153216 | AB5: =(IF(Q5="V",H5,0)+IF(S5="V",H5,0)+IF(R5="V",I5,0)+IF(T5="V",I5,0))/1000*N5 -> 0 | AD5: 0000 (E1-E3-E2-E4) | AE5: #16004
A6: S16_D1-FRONT | B6: D1 egy magas front | C6: D1 | D6: LAP | E6: M03 | F6: Füstös barnásszürke finom faerezet | G6: 18 | H6: 432 | I6: 378 | J6: 428 | K6: 374 | L6: 440 | M6: 386 | N6: 1 | O6: U | P6: +Y (elöl (szoba)) | Q6: V | R6: V | S6: V | T6: V | U6: ABS 2 mm Egger H1399 ST10 dekoregyező, R2 lekerekítés | V6: E1+E4 | W6: 0 | X6: 0 | Y6: 0 | Z6: – | AA6: =H6*I6/1000000*N6 -> 0.163296 | AB6: =(IF(Q6="V",H6,0)+IF(S6="V",H6,0)+IF(R6="V",I6,0)+IF(T6="V",I6,0))/1000*N6 -> 1.62 | AD6: VVVV (E1-E3-E2-E4) | AE6: #16005
A7: S16_D1-BOX-L | B7: D1 fiókoldal | C7: D1 | D7: LAP | E7: M07 | F7: 15 mm nyír rétegelt lemez, matt vízbázisú lakk | G7: 15 | H7: 290 | I7: 237 | J7: 290 | K7: 237 | L7: 290 | M7: 237 | N7: 1 | O7: – | P7: -X (bal) | Q7: L | R7: L | S7: L | T7: L | U7: csiszolt + lakkozott látszó rétegelt él | V7: E1+E4 | W7: 0 | X7: 0 | Y7: 1 | Z7: S16_D1-BOX-L_A.mpr | AA7: =H7*I7/1000000*N7 -> 0.06873 | AB7: =(IF(Q7="V",H7,0)+IF(S7="V",H7,0)+IF(R7="V",I7,0)+IF(T7="V",I7,0))/1000*N7 -> 0 | AD7: LLLL (E1-E3-E2-E4) | AE7: #16006
A8: S16_D1-BOX-R | B8: D1 fiókoldal | C8: D1 | D8: LAP | E8: M07 | F8: 15 mm nyír rétegelt lemez, matt vízbázisú lakk | G8: 15 | H8: 290 | I8: 237 | J8: 290 | K8: 237 | L8: 290 | M8: 237 | N8: 1 | O8: – | P8: -X (bal) | Q8: L | R8: L | S8: L | T8: L | U8: csiszolt + lakkozott látszó rétegelt él | V8: E1+E4 | W8: 0 | X8: 0 | Y8: 1 | Z8: S16_D1-BOX-R_A.mpr | AA8: =H8*I8/1000000*N8 -> 0.06873 | AB8: =(IF(Q8="V",H8,0)+IF(S8="V",H8,0)+IF(R8="V",I8,0)+IF(T8="V",I8,0))/1000*N8 -> 0 | AD8: LLLL (E1-E3-E2-E4) | AE8: #16007
A9: S16_D1-BOX-F | B9: D1 dobozelő/hát | C9: D1 | D9: LAP | E9: M07 | F9: 15 mm nyír rétegelt lemez, matt vízbázisú lakk | G9: 15 | H9: 357 | I9: 210 | J9: 357 | K9: 210 | L9: 357 | M9: 210 | N9: 1 | O9: – | P9: +Y (elöl (szoba)) | Q9: 0 | R9: 0 | S9: L | T9: 0 | U9: csiszolt + lakkozott látszó rétegelt él | V9: E1+E4 | W9: 0 | X9: 0 | Y9: 0 | Z9: – | AA9: =H9*I9/1000000*N9 -> 0.07497 | AB9: =(IF(Q9="V",H9,0)+IF(S9="V",H9,0)+IF(R9="V",I9,0)+IF(T9="V",I9,0))/1000*N9 -> 0 | AD9: L000 (E3-E1-E2-E4) | AE9: #16008
A10: S16_D1-BOX-H | B10: D1 dobozelő/hát | C10: D1 | D10: LAP | E10: M07 | F10: 15 mm nyír rétegelt lemez, matt vízbázisú lakk | G10: 15 | H10: 357 | I10: 210 | J10: 357 | K10: 210 | L10: 357 | M10: 210 | N10: 1 | O10: – | P10: +Y (elöl (szoba)) | Q10: 0 | R10: 0 | S10: L | T10: 0 | U10: csiszolt + lakkozott látszó rétegelt él | V10: E1+E4 | W10: 0 | X10: 0 | Y10: 0 | Z10: – | AA10: =H10*I10/1000000*N10 -> 0.07497 | AB10: =(IF(Q10="V",H10,0)+IF(S10="V",H10,0)+IF(R10="V",I10,0)+IF(T10="V",I10,0))/1000*N10 -> 0 | AD10: L000 (E3-E1-E2-E4) | AE10: #16009
A11: S16_D1-BOX-B | B11: D1 fiókfenék | C11: D1 | D11: LAP | E11: M07 | F11: 15 mm nyír rétegelt lemez, matt vízbázisú lakk | G11: 15 | H11: 357 | I11: 290 | J11: 357 | K11: 290 | L11: 357 | M11: 290 | N11: 1 | O11: – | P11: +Z (fent) | Q11: L | R11: 0 | S11: L | T11: 0 | U11: csiszolt + lakkozott látszó rétegelt él | V11: E1+E4 | W11: 0 | X11: 0 | Y11: 0 | Z11: – | AA11: =H11*I11/1000000*N11 -> 0.10353 | AB11: =(IF(Q11="V",H11,0)+IF(S11="V",H11,0)+IF(R11="V",I11,0)+IF(T11="V",I11,0))/1000*N11 -> 0 | AD11: LL00 (E1-E3-E2-E4) | AE11: #16010
A12: S16_D2-L | B12: D2 korpuszoldal | C12: D2 | D12: LAP | E12: M01 | F12: 18 mm kétoldalt melaminos grafitszürke bútorlap | G12: 18 | H12: 337 | I12: 420 | J12: 336.2 | K12: 418.4 | L12: 337.2 | M12: 420.4 | N12: 1 | O12: – | P12: -X (bal) | Q12: V | R12: V | S12: V | T12: 0 | U12: ABS 0,8 mm Egger U741 ST9 (dekoregyező); ABS 1 mm grafit / festett; ABS 1 mm, a látszó felső felület színében (exposed_top_finish) | V12: E1+E4 | W12: 0 | X12: 9 | Y12: 0 | Z12: S16_D2-L_B.mpr | AA12: =H12*I12/1000000*N12 -> 0.14154 | AB12: =(IF(Q12="V",H12,0)+IF(S12="V",H12,0)+IF(R12="V",I12,0)+IF(T12="V",I12,0))/1000*N12 -> 1.094 | AD12: V0VV (E2-E4-E1-E3) | AE12: #16011
A13: S16_D2-R | B13: D2 korpuszoldal | C13: D2 | D13: LAP | E13: M01 | F13: 18 mm kétoldalt melaminos grafitszürke bútorlap | G13: 18 | H13: 337 | I13: 420 | J13: 336.2 | K13: 418.4 | L13: 337.2 | M13: 420.4 | N13: 1 | O13: – | P13: -X (bal) | Q13: V | R13: V | S13: V | T13: 0 | U13: ABS 0,8 mm Egger U741 ST9 (dekoregyező); ABS 1 mm grafit / festett; ABS 1 mm, a látszó felső felület színében (exposed_top_finish) | V13: E1+E4 | W13: 9 | X13: 0 | Y13: 0 | Z13: S16_D2-R_A.mpr | AA13: =H13*I13/1000000*N13 -> 0.14154 | AB13: =(IF(Q13="V",H13,0)+IF(S13="V",H13,0)+IF(R13="V",I13,0)+IF(T13="V",I13,0))/1000*N13 -> 1.094 | AD13: V0VV (E2-E4-E1-E3) | AE13: #16012
... A59: S16_D6-T | B59: D6 fenék/tető | C59: D6 | D59: LAP | E59: M02 | F59: Szatén sötét barnásgrafit keret | G59: 18 | H59: 327 | I59: 337 | J59: 327 | K59: 337 | L59: 337 | M59: 347 | N59: 1 | O59: – | P59: +Z (fent) | Q59: F | R59: 0 | S59: F | T59: 0 | U59: festett él (festett MDF) | V59: E1+E4 | W59: 0 | X59: 2 | Y59: 8 | Z59: S16_D6-T_A.mpr, S16_D6-T_B.mpr | AA59: =H59*I59/1000000*N59 -> 0.110199 | AB59: =(IF(Q59="V",H59,0)+IF(S59="V",H59,0)+IF(R59="V",I59,0)+IF(T59="V",I59,0))/1000*N59 -> 0 | AD59: 00FF (E2-E4-E1-E3) | AE59: #16058
A60: S16_D6-BACK | B60: D6 bontható hát | C60: D6 | D60: LAP | E60: M08 | F60: 8 mm grafit hátlap | G60: 8 | H60: 389 | I60: 384 | J60: 389 | K60: 384 | L60: 389 | M60: 384 | N60: 1 | O60: – | P60: +Y (elöl (szoba)) | Q60: 0 | R60: 0 | S60: 0 | T60: 0 | U60: – | V60: E1+E4 | W60: 0 | X60: 0 | Y60: 0 | Z60: – | AA60: =H60*I60/1000000*N60 -> 0.149376 | AB60: =(IF(Q60="V",H60,0)+IF(S60="V",H60,0)+IF(R60="V",I60,0)+IF(T60="V",I60,0))/1000*N60 -> 0 | AC60: Kontúros alkatrész: az E1–E4 a befoglaló oldalait jelöli; ívelt élszakasz élzárása (min. rádiusz) műhelyi kérdés. | AD60: 0000 (E1-E3-E2-E4) | AE60: #16059
A61: S16_D6-FRONT | B61: D6 egy magas front | C61: D6 | D61: LAP | E61: M03 | F61: Füstös barnásszürke finom faerezet | G61: 18 | H61: 402.5 | I61: 378 | J61: 398.5 | K61: 374 | L61: 410.5 | M61: 386 | N61: 1 | O61: U | P61: +Y (elöl (szoba)) | Q61: V | R61: V | S61: V | T61: V | U61: ABS 2 mm Egger H1399 ST10 dekoregyező, R2 lekerekítés | V61: E1+E4 | W61: 0 | X61: 0 | Y61: 0 | Z61: – | AA61: =H61*I61/1000000*N61 -> 0.152145 | AB61: =(IF(Q61="V",H61,0)+IF(S61="V",H61,0)+IF(R61="V",I61,0)+IF(T61="V",I61,0))/1000*N61 -> 1.561 | AC61: Kontúros alkatrész: az E1–E4 a befoglaló oldalait jelöli; ívelt élszakasz élzárása (min. rádiusz) műhelyi kérdés. | AD61: VVVV (E1-E3-E2-E4) | AE61: #16060
A62: S16_D6-BOX-L | B62: D6 fiókoldal | C62: D6 | D62: LAP | E62: M07 | F62: 15 mm nyír rétegelt lemez, matt vízbázisú lakk | G62: 15 | H62: 290 | I62: 202 | J62: 290 | K62: 202 | L62: 290 | M62: 202 | N62: 1 | O62: – | P62: -X (bal) | Q62: L | R62: L | S62: L | T62: L | U62: csiszolt + lakkozott látszó rétegelt él | V62: E1+E4 | W62: 0 | X62: 0 | Y62: 1 | Z62: S16_D6-BOX-L_A.mpr | AA62: =H62*I62/1000000*N62 -> 0.05858 | AB62: =(IF(Q62="V",H62,0)+IF(S62="V",H62,0)+IF(R62="V",I62,0)+IF(T62="V",I62,0))/1000*N62 -> 0 | AD62: LLLL (E1-E3-E2-E4) | AE62: #16061
A63: S16_D6-BOX-R | B63: D6 fiókoldal | C63: D6 | D63: LAP | E63: M07 | F63: 15 mm nyír rétegelt lemez, matt vízbázisú lakk | G63: 15 | H63: 290 | I63: 202 | J63: 290 | K63: 202 | L63: 290 | M63: 202 | N63: 1 | O63: – | P63: -X (bal) | Q63: L | R63: L | S63: L | T63: L | U63: csiszolt + lakkozott látszó rétegelt él | V63: E1+E4 | W63: 0 | X63: 0 | Y63: 1 | Z63: S16_D6-BOX-R_A.mpr | AA63: =H63*I63/1000000*N63 -> 0.05858 | AB63: =(IF(Q63="V",H63,0)+IF(S63="V",H63,0)+IF(R63="V",I63,0)+IF(T63="V",I63,0))/1000*N63 -> 0 | AD63: LLLL (E1-E3-E2-E4) | AE63: #16062
A64: S16_D6-BOX-F | B64: D6 dobozelő/hát | C64: D6 | D64: LAP | E64: M07 | F64: 15 mm nyír rétegelt lemez, matt vízbázisú lakk | G64: 15 | H64: 347 | I64: 175 | J64: 347 | K64: 175 | L64: 347 | M64: 175 | N64: 1 | O64: – | P64: +Y (elöl (szoba)) | Q64: 0 | R64: 0 | S64: L | T64: 0 | U64: csiszolt + lakkozott látszó rétegelt él | V64: E1+E4 | W64: 0 | X64: 0 | Y64: 0 | Z64: – | AA64: =H64*I64/1000000*N64 -> 0.060725 | AB64: =(IF(Q64="V",H64,0)+IF(S64="V",H64,0)+IF(R64="V",I64,0)+IF(T64="V",I64,0))/1000*N64 -> 0 | AD64: L000 (E3-E1-E2-E4) | AE64: #16063
A65: S16_D6-BOX-H | B65: D6 dobozelő/hát | C65: D6 | D65: LAP | E65: M07 | F65: 15 mm nyír rétegelt lemez, matt vízbázisú lakk | G65: 15 | H65: 347 | I65: 175 | J65: 347 | K65: 175 | L65: 347 | M65: 175 | N65: 1 | O65: – | P65: +Y (elöl (szoba)) | Q65: 0 | R65: 0 | S65: L | T65: 0 | U65: csiszolt + lakkozott látszó rétegelt él | V65: E1+E4 | W65: 0 | X65: 0 | Y65: 0 | Z65: – | AA65: =H65*I65/1000000*N65 -> 0.060725 | AB65: =(IF(Q65="V",H65,0)+IF(S65="V",H65,0)+IF(R65="V",I65,0)+IF(T65="V",I65,0))/1000*N65 -> 0 | AD65: L000 (E3-E1-E2-E4) | AE65: #16064
A66: S16_D6-BOX-B | B66: D6 fiókfenék | C66: D6 | D66: LAP | E66: M07 | F66: 15 mm nyír rétegelt lemez, matt vízbázisú lakk | G66: 15 | H66: 347 | I66: 290 | J66: 347 | K66: 290 | L66: 347 | M66: 290 | N66: 1 | O66: – | P66: +Z (fent) | Q66: L | R66: 0 | S66: L | T66: 0 | U66: csiszolt + lakkozott látszó rétegelt él | V66: E1+E4 | W66: 0 | X66: 0 | Y66: 0 | Z66: – | AA66: =H66*I66/1000000*N66 -> 0.10063 | AB66: =(IF(Q66="V",H66,0)+IF(S66="V",H66,0)+IF(R66="V",I66,0)+IF(T66="V",I66,0))/1000*N66 -> 0 | AD66: LL00 (E1-E3-E2-E4) | AE66: #16065
A67: S16_T-L | B67: Torony oldallap | C67: TORONY | D67: LAP | E67: M01 | F67: 18 mm kétoldalt melaminos grafitszürke bútorlap | G67: 18 | H67: 337 | I67: 2525 | J67: 336.2 | K67: 2525 | L67: 337.2 | M67: 2525 | N67: 1 | O67: – | P67: -X (bal) | Q67: 0 | R67: V | S67: 0 | T67: 0 | U67: ABS 0,8 mm Egger U741 ST9 (dekoregyező) | V67: E1+E4 | W67: 0 | X67: 49 | Y67: 10 | Z67: S16_T-L_A.mpr, S16_T-L_B.mpr | AA67: =H67*I67/1000000*N67 -> 0.850925 | AB67: =(IF(Q67="V",H67,0)+IF(S67="V",H67,0)+IF(R67="V",I67,0)+IF(T67="V",I67,0))/1000*N67 -> 2.525 | AD67: V000 (E2-E4-E1-E3) | AE67: #16066
A68: S16_T-R | B68: Torony oldallap | C68: TORONY | D68: LAP | E68: M02 | F68: Szatén sötét barnásgrafit keret | G68: 18 | H68: 337 | I68: 2205 | J68: 337 | K68: 2205 | L68: 347 | M68: 2215 | N68: 1 | O68: – | P68: +X (jobb) | Q68: 0 | R68: F | S68: 0 | T68: F | U68: festett él (festett MDF) | V68: E1+E4 | W68: 0 | X68: 45 | Y68: 8 | Z68: S16_T-R_A.mpr, S16_T-R_B.mpr | AA68: =H68*I68/1000000*N68 -> 0.743085 | AB68: =(IF(Q68="V",H68,0)+IF(S68="V",H68,0)+IF(R68="V",I68,0)+IF(T68="V",I68,0))/1000*N68 -> 0 | AD68: FF00 (E4-E2-E1-E3) | AE68: #16067
A69: S16_T-B | B69: Torony fenék/tető | C69: TORONY | D69: LAP | E69: M01 | F69: 18 mm kétoldalt melaminos grafitszürke bútorlap | G69: 18 | H69: 834 | I69: 337 | J69: 834 | K69: 336.2 | L69: 834 | M69: 337.2 | N69: 1 | O69: – | P69: +Z (fent) | Q69: V | R69: 0 | S69: 0 | T69: 0 | U69: ABS 0,8 mm Egger U741 ST9 (dekoregyező) | V69: E1+E4 | W69: 3 | X69: 6 | Y69: 6 | Z69: S16_T-B_A.mpr, S16_T-B_B.mpr | AA69: =H69*I69/1000000*N69 -> 0.281058 | AB69: =(IF(Q69="V",H69,0)+IF(S69="V",H69,0)+IF(R69="V",I69,0)+IF(T69="V",I69,0))/1000*N69 -> 0.834 | AD69: V000 (E1-E3-E2-E4) | AE69: #16068
A70: S16_T-C | B70: Torony középosztó | C70: TORONY | D70: LAP | E70: M01 | F70: 18 mm kétoldalt melaminos grafitszürke bútorlap | G70: 18 | H70: 337 | I70: 2269 | J70: 336.2 | K70: 2269 | L70: 337.2 | M70: 2269 | N70: 1 | O70: – | P70: -X (bal) | Q70: 0 | R70: V | S70: 0 | T70: 0 | U70: ABS 0,8 mm Egger U741 ST9 (dekoregyező) | V70: E1+E4 | W70: 32 | X70: 30 | Y70: 8 | Z70: S16_T-C_A.mpr, S16_T-C_B.mpr | AA70: =H70*I70/1000000*N70 -> 0.764653 | AB70: =(IF(Q70="V",H70,0)+IF(S70="V",H70,0)+IF(R70="V",I70,0)+IF(T70="V",I70,0))/1000*N70 -> 2.269 | AD70: V000 (E2-E4-E1-E3) | AE70: #16069
A71: S16_T-L-S1 | B71: Állítható polc | C71: TORONY | D71: LAP | E71: M01 | F71: 18 mm kétoldalt melaminos grafitszürke bútorlap | G71: 18 | H71: 406 | I71: 290 | J71: 406 | K71: 289.2 | L71: 406 | M71: 290.2 | N71: 1 | O71: – | P71: +Z (fent) | Q71: V | R71: 0 | S71: 0 | T71: 0 | U71: ABS 0,8 mm Egger U741 ST9 (dekoregyező) | V71: E1+E4 | W71: 0 | X71: 0 | Y71: 0 | Z71: – | AA71: =H71*I71/1000000*N71 -> 0.11774 | AB71: =(IF(Q71="V",H71,0)+IF(S71="V",H71,0)+IF(R71="V",I71,0)+IF(T71="V",I71,0))/1000*N71 -> 0.406 | AD71: V000 (E1-E3-E2-E4) | AE71: #16070
A72: S16_T-L-S2 | B72: Állítható polc | C72: TORONY | D72: LAP | E72: M01 | F72: 18 mm kétoldalt melaminos grafitszürke bútorlap | G72: 18 | H72: 406 | I72: 290 | J72: 406 | K72: 289.2 | L72: 406 | M72: 290.2 | N72: 1 | O72: – | P72: +Z (fent) | Q72: V | R72: 0 | S72: 0 | T72: 0 | U72: ABS 0,8 mm Egger U741 ST9 (dekoregyező) | V72: E1+E4 | W72: 0 | X72: 0 | Y72: 0 | Z72: – | AA72: =H72*I72/1000000*N72 -> 0.11774 | AB72: =(IF(Q72="V",H72,0)+IF(S72="V",H72,0)+IF(R72="V",I72,0)+IF(T72="V",I72,0))/1000*N72 -> 0.406 | AD72: V000 (E1-E3-E2-E4) | AE72: #16071
A73: S16_T-L-S3 | B73: Állítható polc | C73: TORONY | D73: LAP | E73: M01 | F73: 18 mm kétoldalt melaminos grafitszürke bútorlap | G73: 18 | H73: 406 | I73: 290 | J73: 406 | K73: 289.2 | L73: 406 | M73: 290.2 | N73: 1 | O73: – | P73: +Z (fent) | Q73: V | R73: 0 | S73: 0 | T73: 0 | U73: ABS 0,8 mm Egger U741 ST9 (dekoregyező) | V73: E1+E4 | W73: 0 | X73: 0 | Y73: 0 | Z73: – | AA73: =H73*I73/1000000*N73 -> 0.11774 | AB73: =(IF(Q73="V",H73,0)+IF(S73="V",H73,0)+IF(R73="V",I73,0)+IF(T73="V",I73,0))/1000*N73 -> 0.406 | AD73: V000 (E1-E3-E2-E4) | AE73: #16072
... A75: S16_T-L-S5 | B75: Állítható polc | C75: TORONY | D75: LAP | E75: M01 | F75: 18 mm kétoldalt melaminos grafitszürke bútorlap | G75: 18 | H75: 406 | I75: 290 | J75: 406 | K75: 289.2 | L75: 406 | M75: 290.2 | N75: 1 | O75: – | P75: +Z (fent) | Q75: V | R75: 0 | S75: 0 | T75: 0 | U75: ABS 0,8 mm Egger U741 ST9 (dekoregyező) | V75: E1+E4 | W75: 0 | X75: 0 | Y75: 0 | Z75: – | AA75: =H75*I75/1000000*N75 -> 0.11774 | AB75: =(IF(Q75="V",H75,0)+IF(S75="V",H75,0)+IF(R75="V",I75,0)+IF(T75="V",I75,0))/1000*N75 -> 0.406 | AD75: V000 (E1-E3-E2-E4) | AE75: #16074
A76: S16_T-L-BACK | B76: Bontható felső hát | C76: TORONY | D76: LAP | E76: M08 | F76: 8 mm grafit hátlap | G76: 8 | H76: 406 | I76: 1921 | J76: 406 | K76: 1921 | L76: 406 | M76: 1921 | N76: 1 | O76: – | P76: +Y (elöl (szoba)) | Q76: 0 | R76: 0 | S76: 0 | T76: 0 | U76: – | V76: E1+E4 | W76: 0 | X76: 0 | Y76: 0 | Z76: – | AA76: =H76*I76/1000000*N76 -> 0.779926 | AB76: =(IF(Q76="V",H76,0)+IF(S76="V",H76,0)+IF(R76="V",I76,0)+IF(T76="V",I76,0))/1000*N76 -> 0 | AC76: Kontúros alkatrész: az E1–E4 a befoglaló oldalait jelöli; ívelt élszakasz élzárása (min. rádiusz) műhelyi kérdés. | AD76: 0000 (E2-E4-E1-E3) | AE76: #16075
A77: S16_T-L-SERVICE | B77: Bontható alsó szervizfedél | C77: TORONY | D77: LAP | E77: M08 | F77: 8 mm grafit hátlap | G77: 8 | H77: 406 | I77: 345 | J77: 404.4 | K77: 343.4 | L77: 404.4 | M77: 343.4 | N77: 1 | O77: – | P77: +Y (elöl (szoba)) | Q77: V | R77: V | S77: V | T77: V | U77: ABS 0,8 mm grafit (csak szervizfedél) | V77: E1+E4 | W77: 0 | X77: 0 | Y77: 0 | Z77: – | AA77: =H77*I77/1000000*N77 -> 0.14007 | AB77: =(IF(Q77="V",H77,0)+IF(S77="V",H77,0)+IF(R77="V",I77,0)+IF(T77="V",I77,0))/1000*N77 -> 1.502 | AD77: VVVV (E1-E3-E2-E4) | AE77: #16076
A78: S16_T-R-S1 | B78: Állítható polc | C78: TORONY | D78: LAP | E78: M01 | F78: 18 mm kétoldalt melaminos grafitszürke bútorlap | G78: 18 | H78: 406 | I78: 290 | J78: 406 | K78: 289.2 | L78: 406 | M78: 290.2 | N78: 1 | O78: – | P78: +Z (fent) | Q78: V | R78: 0 | S78: 0 | T78: 0 | U78: ABS 0,8 mm Egger U741 ST9 (dekoregyező) | V78: E1+E4 | W78: 0 | X78: 0 | Y78: 0 | Z78: – | AA78: =H78*I78/1000000*N78 -> 0.11774 | AB78: =(IF(Q78="V",H78,0)+IF(S78="V",H78,0)+IF(R78="V",I78,0)+IF(T78="V",I78,0))/1000*N78 -> 0.406 | AD78: V000 (E1-E3-E2-E4) | AE78: #16077
A79: S16_T-R-S2 | B79: Állítható polc | C79: TORONY | D79: LAP | E79: M01 | F79: 18 mm kétoldalt melaminos grafitszürke bútorlap | G79: 18 | H79: 406 | I79: 290 | J79: 406 | K79: 289.2 | L79: 406 | M79: 290.2 | N79: 1 | O79: – | P79: +Z (fent) | Q79: V | R79: 0 | S79: 0 | T79: 0 | U79: ABS 0,8 mm Egger U741 ST9 (dekoregyező) | V79: E1+E4 | W79: 0 | X79: 0 | Y79: 0 | Z79: – | AA79: =H79*I79/1000000*N79 -> 0.11774 | AB79: =(IF(Q79="V",H79,0)+IF(S79="V",H79,0)+IF(R79="V",I79,0)+IF(T79="V",I79,0))/1000*N79 -> 0.406 | AD79: V000 (E1-E3-E2-E4) | AE79: #16078
A80: S16_T-R-S3 | B80: Állítható polc | C80: TORONY | D80: LAP | E80: M01 | F80: 18 mm kétoldalt melaminos grafitszürke bútorlap | G80: 18 | H80: 406 | I80: 290 | J80: 406 | K80: 289.2 | L80: 406 | M80: 290.2 | N80: 1 | O80: – | P80: +Z (fent) | Q80: V | R80: 0 | S80: 0 | T80: 0 | U80: ABS 0,8 mm Egger U741 ST9 (dekoregyező) | V80: E1+E4 | W80: 0 | X80: 0 | Y80: 0 | Z80: – | AA80: =H80*I80/1000000*N80 -> 0.11774 | AB80: =(IF(Q80="V",H80,0)+IF(S80="V",H80,0)+IF(R80="V",I80,0)+IF(T80="V",I80,0))/1000*N80 -> 0.406 | AD80: V000 (E1-E3-E2-E4) | AE80: #16079
A81: S16_T-R-S4 | B81: Állítható polc | C81: TORONY | D81: LAP | E81: M01 | F81: 18 mm kétoldalt melaminos grafitszürke bútorlap | G81: 18 | H81: 406 | I81: 290 | J81: 406 | K81: 289.2 | L81: 406 | M81: 290.2 | N81: 1 | O81: – | P81: +Z (fent) | Q81: V | R81: 0 | S81: 0 | T81: 0 | U81: ABS 0,8 mm Egger U741 ST9 (dekoregyező) | V81: E1+E4 | W81: 0 | X81: 0 | Y81: 0 | Z81: – | AA81: =H81*I81/1000000*N81 -> 0.11774 | AB81: =(IF(Q81="V",H81,0)+IF(S81="V",H81,0)+IF(R81="V",I81,0)+IF(T81="V",I81,0))/1000*N81 -> 0.406 | AD81: V000 (E1-E3-E2-E4) | AE81: #16080
A82: S16_T-R-S5 | B82: Állítható polc | C82: TORONY | D82: LAP | E82: M01 | F82: 18 mm kétoldalt melaminos grafitszürke bútorlap | G82: 18 | H82: 406 | I82: 290 | J82: 406 | K82: 289.2 | L82: 406 | M82: 290.2 | N82: 1 | O82: – | P82: +Z (fent) | Q82: V | R82: 0 | S82: 0 | T82: 0 | U82: ABS 0,8 mm Egger U741 ST9 (dekoregyező) | V82: E1+E4 | W82: 0 | X82: 0 | Y82: 0 | Z82: – | AA82: =H82*I82/1000000*N82 -> 0.11774 | AB82: =(IF(Q82="V",H82,0)+IF(S82="V",H82,0)+IF(R82="V",I82,0)+IF(T82="V",I82,0))/1000*N82 -> 0.406 | AD82: V000 (E1-E3-E2-E4) | AE82: #16081
A83: S16_T-R-BACK | B83: Bontható felső hát | C83: TORONY | D83: LAP | E83: M08 | F83: 8 mm grafit hátlap | G83: 8 | H83: 406 | I83: 1921 | J83: 406 | K83: 1921 | L83: 406 | M83: 1921 | N83: 1 | O83: – | P83: +Y (elöl (szoba)) | Q83: 0 | R83: 0 | S83: 0 | T83: 0 | U83: – | V83: E1+E4 | W83: 0 | X83: 0 | Y83: 0 | Z83: – | AA83: =H83*I83/1000000*N83 -> 0.779926 | AB83: =(IF(Q83="V",H83,0)+IF(S83="V",H83,0)+IF(R83="V",I83,0)+IF(T83="V",I83,0))/1000*N83 -> 0 | AC83: Kontúros alkatrész: az E1–E4 a befoglaló oldalait jelöli; ívelt élszakasz élzárása (min. rádiusz) műhelyi kérdés. | AD83: 0000 (E2-E4-E1-E3) | AE83: #16082
A84: S16_T-R-SERVICE | B84: Bontható alsó szervizfedél | C84: TORONY | D84: LAP | E84: M08 | F84: 8 mm grafit hátlap | G84: 8 | H84: 406 | I84: 345 | J84: 404.4 | K84: 343.4 | L84: 404.4 | M84: 343.4 | N84: 1 | O84: – | P84: +Y (elöl (szoba)) | Q84: V | R84: V | S84: V | T84: V | U84: ABS 0,8 mm grafit (csak szervizfedél) | V84: E1+E4 | W84: 0 | X84: 0 | Y84: 0 | Z84: – | AA84: =H84*I84/1000000*N84 -> 0.14007 | AB84: =(IF(Q84="V",H84,0)+IF(S84="V",H84,0)+IF(R84="V",I84,0)+IF(T84="V",I84,0))/1000*N84 -> 1.502 | AD84: VVVV (E1-E3-E2-E4) | AE84: #16083
A85: S16_T-DOOR-L | B85: Torony ajtó | C85: TORONY | D85: LAP | E85: M03 | F85: Füstös barnásszürke finom faerezet | G85: 18 | H85: 412.5 | I85: 2683 | J85: 408.5 | K85: 2679 | L85: 420.5 | M85: 2691 | N85: 1 | O85: V | P85: +Y (elöl (szoba)) | Q85: V | R85: V | S85: V | T85: V | U85: ABS 2 mm Egger H1399 ST10 dekoregyező, R2 lekerekítés | V85: E1+E4 | W85: 0 | X85: 18 | Y85: 0 | Z85: S16_T-DOOR-L_B.mpr | AA85: =H85*I85/1000000*N85 -> 1.1067375 | AB85: =(IF(Q85="V",H85,0)+IF(S85="V",H85,0)+IF(R85="V",I85,0)+IF(T85="V",I85,0))/1000*N85 -> 6.191 | AC85: Kontúros alkatrész: az E1–E4 a befoglaló oldalait jelöli; ívelt élszakasz élzárása (min. rádiusz) műhelyi kérdés. | AD85: VVVV (E2-E4-E1-E3) | AE85: #16084
A86: S16_T-DOOR-R | B86: Torony ajtó | C86: TORONY | D86: LAP | E86: M03 | F86: Füstös barnásszürke finom faerezet | G86: 18 | H86: 412.5 | I86: 2281 | J86: 408.5 | K86: 2277 | L86: 420.5 | M86: 2289 | N86: 1 | O86: V | P86: +Y (elöl (szoba)) | Q86: V | R86: V | S86: V | T86: V | U86: ABS 2 mm Egger H1399 ST10 dekoregyező, R2 lekerekítés | V86: E1+E4 | W86: 0 | X86: 15 | Y86: 0 | Z86: S16_T-DOOR-R_B.mpr | AA86: =H86*I86/1000000*N86 -> 0.9409125 | AB86: =(IF(Q86="V",H86,0)+IF(S86="V",H86,0)+IF(R86="V",I86,0)+IF(T86="V",I86,0))/1000*N86 -> 5.387 | AC86: Kontúros alkatrész: az E1–E4 a befoglaló oldalait jelöli; ívelt élszakasz élzárása (min. rádiusz) műhelyi kérdés. | AD86: VVVV (E2-E4-E1-E3) | AE86: #16085
...

Sheet Anyag-összesítő
A1: Anyag | B1: Megnevezés | C1: Darab | D1: Felület m² | E1: Élzáró fm (V) | F1: Tábla m² (becslés) | G1: Hulladék % (becslés) | H1: Tábla db (becslés)
A2: M01 | B2: 18 mm kétoldalt melaminos grafitszürke bútorlap | C2: =SUMIFS(Szabásjegyzék!N:N,Szabásjegyzék!E:E,A2) -> 30 | D2: =SUMIFS(Szabásjegyzék!AA:AA,Szabásjegyzék!E:E,A2) -> 5.592774 | E2: =SUMIFS(Szabásjegyzék!AB:AB,Szabásjegyzék!E:E,A2) -> 23.228 | F2: 5.796 | G2: 0.2 | H2: =IF(F2>0,ROUNDUP(D2*(1+G2)/F2,0),0) -> 2
A3: M02 | B3: Szatén sötét barnásgrafit keret | C3: =SUMIFS(Szabásjegyzék!N:N,Szabásjegyzék!E:E,A3) -> 28 | D3: =SUMIFS(Szabásjegyzék!AA:AA,Szabásjegyzék!E:E,A3) -> 2.506747 | E3: =SUMIFS(Szabásjegyzék!AB:AB,Szabásjegyzék!E:E,A3) -> 0 | F3: 5.796 | G3: 0.2 | H3: =IF(F3>0,ROUNDUP(D3*(1+G3)/F3,0),0) -> 1
A4: M03 | B4: Füstös barnásszürke finom faerezet | C4: =SUMIFS(Szabásjegyzék!N:N,Szabásjegyzék!E:E,A4) -> 9 | D4: =SUMIFS(Szabásjegyzék!AA:AA,Szabásjegyzék!E:E,A4) -> 7.385245 | E4: =SUMIFS(Szabásjegyzék!AB:AB,Szabásjegyzék!E:E,A4) -> 30.789 | F4: 5.796 | G4: 0.2 | H4: =IF(F4>0,ROUNDUP(D4*(1+G4)/F4,0),0) -> 2
A5: M04 | B5: Meleg taupe finom textilhatású háttér | C5: =SUMIFS(Szabásjegyzék!N:N,Szabásjegyzék!E:E,A5) -> 5 | D5: =SUMIFS(Szabásjegyzék!AA:AA,Szabásjegyzék!E:E,A5) -> 13.720525 | E5: =SUMIFS(Szabásjegyzék!AB:AB,Szabásjegyzék!E:E,A5) -> 0 | F5: 5.796 | G5: 0.2 | H5: =IF(F5>0,ROUNDUP(D5*(1+G5)/F5,0),0) -> 3
A6: M05 | B6: Elefántcsont–len színű valódi szövetbetét | C6: =SUMIFS(Szabásjegyzék!N:N,Szabásjegyzék!E:E,A6) -> 1 | D6: =SUMIFS(Szabásjegyzék!AA:AA,Szabásjegyzék!E:E,A6) -> 0.8110875 | E6: =SUMIFS(Szabásjegyzék!AB:AB,Szabásjegyzék!E:E,A6) -> 0 | F6: 0 | G6: 0.2 | H6: =IF(F6>0,ROUNDUP(D6*(1+G6)/F6,0),0) -> 0
A7: M07 | B7: 15 mm nyír rétegelt lemez, matt vízbázisú lakk | C7: =SUMIFS(Szabásjegyzék!N:N,Szabásjegyzék!E:E,A7) -> 30 | D7: =SUMIFS(Szabásjegyzék!AA:AA,Szabásjegyzék!E:E,A7) -> 2.69504 | E7: =SUMIFS(Szabásjegyzék!AB:AB,Szabásjegyzék!E:E,A7) -> 0 | F7: 5.796 | G7: 0.2 | H7: =IF(F7>0,ROUNDUP(D7*(1+G7)/F7,0),0) -> 1
A8: M08 | B8: 8 mm grafit hátlap | C8: =SUMIFS(Szabásjegyzék!N:N,Szabásjegyzék!E:E,A8) -> 11 | D8: =SUMIFS(Szabásjegyzék!AA:AA,Szabásjegyzék!E:E,A8) -> 3.132806 | E8: =SUMIFS(Szabásjegyzék!AB:AB,Szabásjegyzék!E:E,A8) -> 3.004 | F8: 5.796 | G8: 0.2 | H8: =IF(F8>0,ROUNDUP(D8*(1+G8)/F8,0),0) -> 1
A9: M10 | B9: 8 mm MDF léc (rejtett háttér-távtartó) | C9: =SUMIFS(Szabásjegyzék!N:N,Szabásjegyzék!E:E,A9) -> 5 | D9: =SUMIFS(Szabásjegyzék!AA:AA,Szabásjegyzék!E:E,A9) -> 0.447 | E9: =SUMIFS(Szabásjegyzék!AB:AB,Szabásjegyzék!E:E,A9) -> 0 | F9: 5.796 | G9: 0.2 | H9: =IF(F9>0,ROUNDUP(D9*(1+G9)/F9,0),0) -> 1
A10: M11 | B10: 12 mm festett MDF (M02 színben) | C10: =SUMIFS(Szabásjegyzék!N:N,Szabásjegyzék!E:E,A10) -> 1 | D10: =SUMIFS(Szabásjegyzék!AA:AA,Szabásjegyzék!E:E,A10) -> 0.8395625 | E10: =SUMIFS(Szabásjegyzék!AB:AB,Szabásjegyzék!E:E,A10) -> 0 | F10: 5.796 | G10: 0.2 | H10: =IF(F10>0,ROUNDUP(D10*(1+G10)/F10,0),0) -> 1
A11: M12 | B11: Fénytakaró / tálca / baffle profil – termék kiválasztandó | C11: =SUMIFS(Szabásjegyzék!N:N,Szabásjegyzék!E:E,A11) -> 9 | D11: =SUMIFS(Szabásjegyzék!AA:AA,Szabásjegyzék!E:E,A11) -> 0.233193 | E11: =SUMIFS(Szabásjegyzék!AB:AB,Szabásjegyzék!E:E,A11) -> 0 | F11: 0 | G11: 0.2 | H11: =IF(F11>0,ROUNDUP(D11*(1+G11)/F11,0),0) -> 0
A13: Feltételezés: tábla 2800×2070 mm = 5,796 m², hulladék 20 % – becslés, termék nincs kiválasztva (kék = módosítható). M05 szövet és M12 fénytakaró nem táblaanyag (0 = nem számol).

Sheet Vasalat
A1: Tétel | B1: Cikkszám / megnevezés | C1: Db | D1: Forrás | E1: Státusz
A2: 760H3000S | B2: Blum MOVENTO 760H3000S sínpár NL300 (csavarozva, sablon T65.1600.01) | C2: 6 | D2: f2b_vasalat.py – geometriából | E2: TERVI – típus/variáns műhelyi megerősítésre
A3: MINIFIX_15 | B3: Häfele Minifix 15 ház 262.26.174 + csap (GEN_MFX_BOLT_24x5) | C3: 22 | D3: f2b_vasalat.py – geometriából | E3: TERVI – típus/variáns műhelyi megerősítésre
A4: PANT_CLIPTOP_110 | B4: Blum CLIP top 110° rugó nélküli, inset, csavaros 70T3750 | C4: 11 | D4: f2b_vasalat.py – geometriából | E4: TERVI – típus/variáns műhelyi megerősítésre
A5: POLCTARTO | B5: polctartó Ø5 csap – cikkszám az asztalostól (a de_11090 az etalonban konfirmát-jelölő) | C5: 40 | D5: f2b_vasalat.py – geometriából | E5: TERVI – típus/variáns műhelyi megerősítésre
A6: SZINKRON | B6: T60.1125W + 2×T60.000D – szinkronrúd vágási méret: 122 mm | C6: 6 | D6: f2b_vasalat.py – geometriából | E6: TERVI – típus/variáns műhelyi megerősítésre
A7: T51.7601 | B7: Blum MOVENTO frontrögzítő pár T51.7601 (sablonnal előfúrva Ø2,5×10, 75°) | C7: 6 | D7: f2b_vasalat.py – geometriából | E7: TERVI – típus/variáns műhelyi megerősítésre
A8: TIP-ON | B8: Blum TIP-ON BLUMOTION T60L7040 S0 (szerszám nélkül a sínre) | C8: 6 | D8: f2b_vasalat.py – geometriából | E8: TERVI – típus/variáns műhelyi megerősítésre
A9: TIPLI_D6x30 | B9: Ø6×30 bordás bükk tipli (él-él) | C9: 14 | D9: f2b_vasalat.py – geometriából | E9: TERVI – típus/variáns műhelyi megerősítésre
A10: TIPLI_D8x35 | B10: Ø8×35 bordás tipli (etalon: CONNOBJ_DOWEL_D8_L35_13-24) | C10: 111 | D10: f2b_vasalat.py – geometriából | E10: TERVI – típus/variáns műhelyi megerősítésre
A11: PANT talplemez | B11: Blum CLIP talplemez 0 mm 177H3100E | C11: 11 | D11: f2b_vasalat.py | E11: TERVI

Sheet Furatok
A1: Címke-ID | B1: # | C1: Oldal / él | D1: X (U) mm | E1: Y (V) mm | F1: Z (N) mm | G1: Ø mm | H1: Mélység mm | I1: Funkció | J1: Kapcsolat | K1: MPR
A2: S16_D1-L | B2: 1 | C2: E1 | D2: 32 | E2: 0 | F2: 9 | G2: 8 | H2: 25 | I2: TIPLI_EL | J2: D1-L:E1:CURVE-T-BOT:0 | K2: S16_D1-L_A.mpr
A3: S16_D1-L | B3: 2 | C3: E1 | D3: 168.5 | E3: 0 | F3: 9 | G3: 8 | H3: 25 | I3: TIPLI_EL | J3: D1-L:E1:CURVE-T-BOT:1 | K3: S16_D1-L_A.mpr
A4: S16_D1-L | B4: 3 | C4: E1 | D4: 305 | E4: 0 | F4: 9 | G4: 8 | H4: 25 | I4: TIPLI_EL | J4: D1-L:E1:CURVE-T-BOT:2 | K4: S16_D1-L_A.mpr
A5: S16_D1-L | B5: 4 | C5: B | D5: 84.25 | E5: 24 | F5: 0 | G5: 15 | H5: 12.5 | I5: MINIFIX_HAZ | J5: D1-L:E1:CURVE-T-BOT:MF0 | K5: S16_D1-L_B.mpr
A6: S16_D1-L | B6: 5 | C6: E1 | D6: 84.25 | E6: 0 | F6: 9 | G6: 8 | H6: 25 | I6: MINIFIX_CSATORNA | J6: D1-L:E1:CURVE-T-BOT:MF0 | K6: S16_D1-L_A.mpr
A7: S16_D1-L | B7: 6 | C7: B | D7: 252.75 | E7: 24 | F7: 0 | G7: 15 | H7: 12.5 | I7: MINIFIX_HAZ | J7: D1-L:E1:CURVE-T-BOT:MF1 | K7: S16_D1-L_B.mpr
A8: S16_D1-L | B8: 7 | C8: E1 | D8: 252.75 | E8: 0 | F8: 9 | G8: 8 | H8: 25 | I8: MINIFIX_CSATORNA | J8: D1-L:E1:CURVE-T-BOT:MF1 | K8: S16_D1-L_A.mpr
A9: S16_D1-L | B9: 8 | C9: E3 | D9: 32 | E9: 402 | F9: 9 | G9: 8 | H9: 25 | I9: TIPLI_EL | J9: D1-L:E3:T-B:0 | K9: S16_D1-L_A.mpr
A10: S16_D1-L | B10: 9 | C10: E3 | D10: 168.5 | E10: 402 | F10: 9 | G10: 8 | H10: 25 | I10: TIPLI_EL | J10: D1-L:E3:T-B:1 | K10: S16_D1-L_A.mpr
A11: S16_D1-L | B11: 10 | C11: E3 | D11: 305 | E11: 402 | F11: 9 | G11: 8 | H11: 25 | I11: TIPLI_EL | J11: D1-L:E3:T-B:2 | K11: S16_D1-L_A.mpr
A12: S16_D1-L | B12: 11 | C12: B | D12: 305 | E12: 393 | F12: 0 | G12: 8 | H12: 13 | I12: TIPLI_LAP | J12: D1-T:E4:D1-L:0 | K12: S16_D1-L_B.mpr
A13: S16_D1-L | B13: 12 | C13: B | D13: 168.5 | E13: 393 | F13: 0 | G13: 8 | H13: 13 | I13: TIPLI_LAP | J13: D1-T:E4:D1-L:1 | K13: S16_D1-L_B.mpr
... A540: S16_T-LOW-DIV | B540: 10 | C540: E3 | D540: 305 | E540: 402 | F540: 9 | G540: 8 | H540: 25 | I540: TIPLI_EL | J540: T-LOW-DIV:E3:T-B:2 | K540: S16_T-LOW-DIV_A.mpr

Sheet Nyitott és jelmagyarázat
A1: STÁTUSZ | B1: TERVI – NEM GYÁRTÁSI KIADÁS · S16-R15C-GY-v1 · 2026-10-30
A2: Koordináták | B2: X = helyi U (hossz), Y = helyi V (szélesség), az A oldal felől nézve; 0,0 = E1+E4 sarok (javasolt gépi ütköző).
A3: Él-kód | B3: E1-E2-E3-E4 sorrend (E1 alsó, E2 jobb, E3 felső, E4 bal az A oldal felől). V = élzárt (ABS), F = festett, L = lakkozott, K = kárpitozott, 0 = nincs.
A4: Asztalos konvenció | B4: Az etalon él-kódjának (pl. V0VV) sorrendje és az 'A' jel jelentése még nincs megerősítve – a válasz után átállítható.
A5: MPR | B5: woodWOP TERVEZET (VERSION 4.0 formátum, csak furatok). Gépre kész csak az asztalos minta-MPR-je, szerszámtáblája és próbadarab után.
A6: Asztalos él-kód | B6: A DWG rétegnevében és a Szabásjegyzék 'Élkód (asztalos)' oszlopában: hossz-él 1 (látszó) – hossz-él 2 – szél-él 1 – szél-él 2, a coo1.dwg mintájára. FELTEVÉS, az asztalos megerősítéséig.
A7: Pánt (S16) | B7: R15B: bal toronyajtó keretszára 50/50 mm → Blum 70T3750 (rugó nélküli inset, TIP-ON) + 177H3100E, B = 3 mm. Péter 2026-10-30 megbízásából Claude döntése, visszafordítható.
A8: Nyitott | B8: Lapanyag/dekor termék és táblaméret; élzáró vastagság és előmarás; polctartó típus; fiók sín furatképe; LED-profilok; helyszíni felmérés.

Sheet Anyagjavaslat
A1: Anyagkód | B1: # | C1: Gyártó | D1: Termékkód | E1: Név | F1: Felület | G1: Vastagság mm | H1: Táblaméret | I1: Élzáró (ABS) | J1: Forgalmazó | K1: Ár | L1: Ár egység / megjegyzés | M1: Ár dátuma | N1: Színegyezés | O1: Forrás | P1: Státusz
A2: M01 | B2: 1 | C2: Egger | D2: U741 ST9 | E2: Lava Grey / Láva szürke (Eurodekor laminált forgácslap) | F2: ST9 Smoothtouch Matt | G2: 18 | H2: 2800x2070 | I2: Egger · ABS E_U741 ST9 – 0,8/23 mm (JAF cikksz. 24744/0741) vagy 2/23 mm (24721/0741) | J2: Lapp-fa Kft. (Budapest XVII. ker. telephely, készleten) / Fabuli Style / JAF Holz Hungária | K2: 29629 | L2: Ft/tábla nettó (Lapp-fa); Fabuli: 37 764 nettó / 47 960 bruttó/tábla; Fabuli él 0,8/23: 230 Ft bruttó (egység nincs kiírva, valószínűleg fm) | M2: 2026-10-30 | N2: Becslés: Egger saját referenciája NCS S 7005-Y20R (nagyon jó egyezés), RAL 7013 – meleg, vöröses grafit; #504942-höz a legközelebbi talált uni. 1 mm-es Egger ABS ehhez a dekorhoz nem látszott a forrásokban (csak 0,4/0,8/2 mm) – 0,8 vagy 2 mm-re kell dönteni, vagy Rehau/Ostermann 1 mm-es párost kérni. | O2: https://lapp-fa.hu/butorlap/u-741-st9-lava-szurke-18mm-2800x2070-154.html https://fabuli.hu/butorlap-egger-uni-u741-st9-lava-szurke-2800x2070x18mm-7646 https://www.jafholz.hu/shop/Dekorativ-lapok/Laminalt-forgacslap/egger-eurodekor-laminalt-forgacslap-lava-szurke-u741-st9~p2204155 https://www.egger.com/en/interior/decor-detail/U741_9?country=GB | P2: JAVASLAT – mintával ellenőrizendő
A3: M01 | B3: 2 | C3: Egger | D3: U748 ST9 | E3: Truffle Brown / Trüffel barna | F3: ST9 Smoothtouch Matt | G3: 18 | H3: 2800x2070 | I3: Egger · ABS E_U748 ST9 – 0,8/23 mm vagy 2,0/23 mm | J3: Lapp-fa Kft. (készleten mindhárom telephelyen) / Fabuli Style | K3: 26534 | L3: Ft/tábla nettó (Lapp-fa); Fabuli: 33 819 nettó / 42 950 bruttó/tábla | M3: 2026-10-30 | N3: Becslés: Egger ref. NCS S 7005-Y50R – barnább, mint a cél; csak akkor, ha a grafit helyett barnásabb korpusz kell. | O3: https://lapp-fa.hu/butorlap/u-748-st9-truffel-18mm-2800x2070-344.html https://fabuli.hu/butorlap-egger-uni-u748-st9-truffel-barna-2800x2070x18mm-7647 https://www.egger.com/en/interior/decor-detail/U748_9?country=GB | P3: JAVASLAT – mintával ellenőrizendő
A4: M02 | B4: 1 | C4: Egger (hordozó) + IVM Chemicals / Milesi (festékrendszer) | D4: Egger MDF natúr 18 mm + Milesi LBR 30 2K PU fehér MDF-alapozó (edző LNB 42, 50%) + Milesi PU pigmentált fedőfesték szatén fokban, NCS-re keverve | E4: Szatén sötét barnásgrafit festett MDF keret | F4: 2K PU, szatén (fényfok a festékrendszer adatlapja szerint, pl. 20–30 gloss – egyeztetendő) | G4: 18 | H4: 2800x2070 | J4: MDF: Lapp-fa Kft. (a forrás szerint jelenleg nincs készleten); festék: M.L.S. Magyarország Kft. (Milesi HU, 2310 Szigetszentmiklós, Sellő u. 8.) | K4: 21694 | L4: Ft/tábla (MDF) nettó; festék ár nincs nyilvános | M4: 2026-10-30 | N4: Szín becslés #332c26-ra: NCS S 8005-Y50R körül; RAL közelítés RAL 8019 (Szürkésbarna) – mindkettő saját becslés, nem gyártói adat. Festett minta (drawdown) MDF-en kötelező. A szatén fedőfesték pontos Milesi-cikkszáma a forgalmazótól kérendő (nyilvánosan nem találtam). | O4: https://lapp-fa.hu/mdf/mdf-egger-natur-18mm-2800x2070-141.html https://www.milesi.hu/ipari-felhasznalok/component/pes/product/66?catid=2212 https://milesi.hu/lakossagi-felhasznalok | P4: JAVASLAT – mintával ellenőrizendő
A5: M02 | B5: 2 | C5: Sayerlack (Sherwin-Williams) festékrendszer | D5: Sayerlack 2K PU pigmentált alapozó + fedő, NCS-re színezve – cikkszám a forgalmazótól | E5: Alternatív festékrendszer ugyanarra az Egger MDF 18 mm hordozóra | F5: 2K PU szatén | G5: 18 | H5: 2800x2070 | J5: Mile Color Kft. (Sayerlack HU szerződött partner, Miskolc) / Lakgruppen | N5: ár nincs nyilvános; termékkód nem látszott a forrásban – csak a márka és forgalmazó igazolt. Az asztalos/fényező saját bevált rendszere is elfogadható, ha NCS-mintát ad. | O5: https://sayerlack.hu/ https://lakgruppen.hu/sayerlack/b/18 | P5: JAVASLAT – mintával ellenőrizendő
A6: M03 | B6: 1 | C6: Egger | D6: H1399 ST10 | E6: Truffle Brown Denver Oak / Trüffel barna Denver tölgy | F6: ST10 Deepskin Rough | G6: 18 | H6: 2800x2070 | I6: Egger · ABS H1399 ST10 (0,8 vagy 2 mm; pontos cikkszám a forgalmazótól) | J6: Lapp-fa Kft. (készleten mindhárom telephelyen) / Fabuli / Szabhatjuk.hu (1037 Bp., Csillaghegyi út 23.) | K6: 34950 | L6: Ft/tábla nettó (Lapp-fa) | M6: 2026-10-30 | N6: Becslés: Egger leírás szerint barna, meleg és hideg tónusok keveréke, finom erezet, kis görcsök, enyhe deszkahatás – a 'füstös barnásszürke' célhoz (#40362e) közel, de görcsös. Erezetirány: tábla hossza 2800 mm mentén fut; magas ajtók függőleges erezetéhez 2800 mm-es irány elég, vízszintes frontoknál a szabásterv ezt vegye figyelembe. Az ABS élhez az ST10 dekorpárt a forgalmazó erősítse meg. | O6: https://lapp-fa.hu/butorlap/h-1399-st10-truffelbarna-denver-tolgy-18mm-2800x2070-672.html https://szabhatjuk.hu/termek/egger-h1399-st10-truffel-barna-denver-tolgy-butorlap/ https://www.egger.com/en/interior/decor-detail/H1399_10?country=GB | P6: JAVASLAT – mintával ellenőrizendő
A7: M03 | B7: 2 | C7: Egger | D7: H1199 ST12 | E7: Black-Brown Thermo Oak / Sötétbarna Thermo tölgy | F7: ST12 Omnipore Matt | G7: 18 | H7: 2800x2070 | I7: Egger · ABS H1199 ST12 – 0,8/23 mm vagy 2,0/23 mm | J7: Fabuli Style (központi raktár, várható 2026-11-10) | K7: 47960 | L7: Ft/tábla bruttó (Fabuli; nettó 37 764); él 0,8/23: 290 Ft bruttó, 2,0/23: 400 Ft bruttó (egység nincs kiírva) | M7: 2026-10-30 | N7: Becslés: sötétebb, kevésbé szürke, mint a cél; nyugodtabb, görcs nélküli 'thermo' karakter. Szín-referenciát (NCS) nem találtam. | O7: https://fabuli.hu/butorlap-egger-fautanzat-h1199-st12-sotetbarna-thermo-tolgy-2800x2070x18mm-7690 | P7: JAVASLAT – mintával ellenőrizendő
A8: M04 | B8: 1 | C8: Egger | D8: U740 ST9 | E8: Dark Taupe / Sötét taupe | F8: ST9 Smoothtouch Matt (NEM textilhatású) | G8: 18 | H8: 2800x2070 | I8: Egger · ABS U740 ST9 (cikkszám a forgalmazótól) | J8: Szabhatjuk.hu (Budapest) – ár nem látszott | N8: ár nincs nyilvános. Becslés: Egger ref. NCS S 5005-Y20R – színben a legközelebbi talált meleg taupe a #706252-höz (a cél kissé sárgásabb/telítettebb), de a felület sima matt, nem textil. Ha a textilhatás fontosabb, lásd 2. jelölt. | O8: https://szabhatjuk.hu/termek/sotet-taupe-butorlap-egger-u740-st9/ https://www.egger.com/en/interior/decor-detail/U740_9?country=GB | P8: JAVASLAT – mintával ellenőrizendő
A9: M04 | B9: 2 | C9: Egger | D9: F416 ST10 | E9: Beige Textile / Bézs textil | F9: ST10 Deepskin Rough – textil/szövet struktúra | G9: 18 | H9: 2800x2070 | I9: Egger · ABS E_F416 ST10 – 0,8/23 mm vagy 2,0/23 mm | J9: Fabuli Style (központi raktár, várható 2026-11-10) / JAF Holz / Szabhatjuk | K9: 45030 | L9: Ft/tábla bruttó (Fabuli; nettó 35 457); él 0,8/23: 280 Ft, 2,0/23: 400 Ft bruttó (egység nincs kiírva) | M9: 2026-10-30 | N9: Becslés: valódi textilhatás, de valószínűleg VILÁGOSABB a #706252-nél (NCS-ref. nem található) – csak mintával dönthető el. Sötét textil-alternatíva: Egger F433 ST10 Antracit len (túl hideg/sötét a célhoz). | O9: https://fabuli.hu/butorlap-egger-fantazia-f416-st10-bezs-textil-2800x2070x18mm-7761 https://www.jafholz.hu/shop/lap--lemez-termekek/dekorativ-lap/laminalt-forgacslap/egger-laminalt-forgacslap-textil-bezs-f416-st10~p6939089 | P9: JAVASLAT – mintával ellenőrizendő
A10: M05 | B10: 1 | C10: Kvadrat | D10: Hallingdal 65, szín 0200 | E10: Hallingdal 65 – bézs/törtfehér melírozott gyapjú kárpitszövet | F10: szövött, 70% új gyapjú / 30% viszkóz, Martindale 100 000 | H10: tekercs, szélesség 1300 mm | J10: Magyar Kvadrat-viszonteladó: paisley.hu (Kvadrat kollekciókat listáz; Hallingdal HU-készlet nem igazolt) – EU-webshop: etoffe.com | K10: 199 | L10: EUR/fm nincs jelölve (etoffe.com, FR; jelenleg nincs készleten) | M10: 2026-10-30 | N10: Becslés: 0200 = bézs és törtfehér szálak keveréke – elefántcsont–len (#c7bca7) hangulathoz illik, pontos árnyalat csak mintával (Kvadrat minta ~4 EUR). Magyar ár nincs nyilvános. Kvadrat 0110 is jelölt lehet, adatát nem tudtam ellenőrizni. | O10: https://audocph.com/collections/hallingdal-65/products/hallingdal-65-0200 https://www.etoffe.com/en/furnishing-fabrics/11771-hallingdal-65-fabric-kvadrat.html https://paisley.hu/kollekciok/fuggony-butorszovet-kollekciok/kvadrat-textil/kvadrat-san-0910-karpit-anyag-butorszovet | P10: JAVASLAT – mintával ellenőrizendő
A11: M07 | B11: 1 | C11: ismeretlen (finn/balti nyír, gyártó nincs megnevezve a forrásban) | D11: Nyír rétegelt lemez 15 mm BB/WG, BFU-100 (DIN 68705), 11 réteg | E11: Nyír rétegelt lemez fiókdobozhoz | F11: mindkét oldal javított, csiszolt; matt vízbázisú lakk külön | G11: 15 | H11: 2500x1250 | J11: OKFT Faáruház (6750 Algyő; webes rendelés) | K11: 38821 | L11: Ft/tábla nincs jelölve a forrásban | M11: 2026-10-30 | N11: Látszó él (rétegzett nyír) – az élminőséget (hézag, foltok) mintával/első táblánál ellenőrizni. Gyártó (pl. Riga Wood/Koskisen) nem igazolt. | O11: https://www.okftfaaruhaz.hu/NYIR-RET-LEM-15mm-BB/WG-vizallo-2500x1250x15mm-BFU | P11: JAVASLAT – mintával ellenőrizendő
A12: M08 | B12: 1 | C12: Egger | D12: U961 ST2 | E12: Graphite Grey – 8 mm kétoldalt melaminos forgácslap | F12: ST2 Smoothtouch Pearl | G12: 8 | H12: 2800x2070 | J12: HU: nem találtam raktári 8 mm-es tételt (Fabuli a 18 mm-es U961 ST2-t 'NEM KAPHATÓ'-nak jelöli); Forest Hungary U961 ST7 18 mm-t listáz – 8 mm csak rendelésre, ellenőrizendő | N12: ár nincs nyilvános (HU). A 8 mm-es U961 ST2 létezése csak brit forgalmazónál látszott. Szín becslés: U961 valószínűleg sötétebb és hidegebb a #696c67-nél. | O12: https://www.lawcris.co.uk/2800mm-x-2070mm-x-8mm-u961-st2-graphite-grey-melamine-faced-chipboard-cmeu961st208 https://fabuli.hu/butorlap-egger-uni-u961-st2-grafit-szurke-2800x2070x18mm-7663 https://www.foresteu.com/laptermekek-es-tartozekaik/butorlap/egger-uni/20010961182-butorlap-egger-uni-u961-st7-grafit-szurke-2800x2070x18mm | P12: JAVASLAT – mintával ellenőrizendő
A13: M08 | B13: 2 | C13: Egger | D13: U963 ST9 | E13: Diamond Grey / Gyémántszürke | F13: ST9 Smoothtouch Matt | G13: 16, 18 | H13: 2800x2070 | I13: Egger · ABS U963 ST9 – 0,8/23 mm (JAF 24744/0963) | J13: JAF Holz Hungária (16 mm: 13113/0963; 18 mm: 13198/0963) | N13: ár nincs nyilvános (JAF bejelentkezéshez köti). ELTÉRÉS: 8 mm helyett 16 mm – csak akkor, ha a hátlap-horony/szerkezet átírható; HU-ban 8 mm-ben nem látszott. Szín becslés: középgrafit, a #696c67-hez valószínűleg közelebb, mint az U961. | O13: https://www.jafholz.hu/shop/lap--lemez-termekek/dekorativ-lap/laminalt-forgacslap/egger-eurodekor-laminalt-forgacslap-gyemantszurke-u963-st9~p12239867 | P13: JAVASLAT – mintával ellenőrizendő
